<robot name="onshape">
<link name="base">
<visual>
<origin xyz="-0.038608271166815956443 0.12440450522789228693 -0.063991340905239182946" rpy="5.7509516044667590244e-15 -2.0862571760163504623e-15 3.6082248300316976197e-16" />
<geometry>
<mesh filename="package:///servo_motor_mg996r.stl"/>
</geometry>
<material name="servo_motor_mg996r_material">
<color rgba="0.35294117647058825815 0.35294117647058825815 0.35294117647058825815 1.0"/>
</material>
</visual>
<collision>
<origin xyz="-0.038608271166815956443 0.12440450522789228693 -0.063991340905239182946" rpy="5.7509516044667590244e-15 -2.0862571760163504623e-15 3.6082248300316976197e-16" />
<geometry>
<mesh filename="package:///servo_motor_mg996r.stl"/>
</geometry>
</collision>
<visual>
<origin xyz="-0.038608271166816053588 0.12440450522789234244 -0.063991340905239169068" rpy="5.807677009606613488e-15 4.8047100793287102735e-17 9.3830639003887794165e-31" />
<geometry>
<mesh filename="package:///base.stl"/>
</geometry>
<material name="base_material">
<color rgba="0.9372549019607843146 0.94117647058823528106 0.94509803921568624752 1.0"/>
</material>
</visual>
<collision>
<origin xyz="-0.038608271166816053588 0.12440450522789234244 -0.063991340905239169068" rpy="5.807677009606613488e-15 4.8047100793287102735e-17 9.3830639003887794165e-31" />
<geometry>
<mesh filename="package:///base.stl"/>
</geometry>
</collision>
<inertial>
<origin xyz="0.002162793611686298495 0.031530345059669964702 -0.0055013484282212653936" rpy="0 0 0"/>
<mass value="5.0548333489920036499" />
<inertia ixx="0.0068327409758256697422" ixy="0.00023690149940151807831"  ixz="-0.00017279538664273868761" iyy="0.0070338527580898644806" iyz="0.00011437036882556746306" izz="0.01084320494057079004" />
</inertial>
</link>

<link name="waist">
<visual>
<origin xyz="-0.040779253635128159816 -0.092879565691815102468 0.093107574107867213664" rpy="3.1415926535897900074 -1.3861331259258425912e-16 3.0388503983682223525e-17" />
<geometry>
<mesh filename="package:///waist.stl"/>
</geometry>
<material name="waist_material">
<color rgba="0.082352941176470587092 0.37647058823529411242 0.74509803921568629193 1.0"/>
</material>
</visual>
<collision>
<origin xyz="-0.040779253635128159816 -0.092879565691815102468 0.093107574107867213664" rpy="3.1415926535897900074 -1.3861331259258425912e-16 3.0388503983682223525e-17" />
<geometry>
<mesh filename="package:///waist.stl"/>
</geometry>
</collision>
<visual>
<origin xyz="-0.040604987428227462543 -0.092909252206131276441 0.093284350803163579302" rpy="3.1415926535897904515 -1.3537750243936206072e-16 -1.1847385475940871091e-15" />
<geometry>
<mesh filename="package:///servo_motor_mg996r_1.stl"/>
</geometry>
<material name="servo_motor_mg996r_1_material">
<color rgba="0.35294117647058825815 0.35294117647058825815 0.35294117647058825815 1.0"/>
</material>
</visual>
<collision>
<origin xyz="-0.040604987428227462543 -0.092909252206131276441 0.093284350803163579302" rpy="3.1415926535897904515 -1.3537750243936206072e-16 -1.1847385475940871091e-15" />
<geometry>
<mesh filename="package:///servo_motor_mg996r_1.stl"/>
</geometry>
</collision>
<inertial>
<origin xyz="0.0009636382974727454977 -0.015447750665147899976 -0.023484589658302735399" rpy="0 0 0"/>
<mass value="0.14242800355200002649" />
<inertia ixx="9.7597148676763860443e-05" ixy="4.2110309635180798486e-06"  ixz="1.0806219757220858301e-05" iyy="9.2815155350301102783e-05" iyz="-2.0598149863689242905e-05" izz="0.00010084520564648440718" />
</inertial>
</link>

<link name="link_1">
<visual>
<origin xyz="-0.038344380354147389323 0.13356083097909682289 0.095646339670104163488" rpy="1.5707963267948930053 0.16873178976647235094 1.6946894064803318076e-17" />
<geometry>
<mesh filename="package:///arm_01.stl"/>
</geometry>
<material name="arm_01_material">
<color rgba="0.082352941176470587092 0.37647058823529411242 0.74509803921568629193 1.0"/>
</material>
</visual>
<collision>
<origin xyz="-0.038344380354147389323 0.13356083097909682289 0.095646339670104163488" rpy="1.5707963267948930053 0.16873178976647235094 1.6946894064803318076e-17" />
<geometry>
<mesh filename="package:///arm_01.stl"/>
</geometry>
</collision>
<visual>
<origin xyz="-0.038344380354147181156 0.13356083097909668411 0.0966086928392866362" rpy="1.5707963267948930053 0.16873178976647235094 1.6946894064803318076e-17" />
<geometry>
<mesh filename="package:///arm_01.stl"/>
</geometry>
<material name="arm_01_material">
<color rgba="0.082352941176470587092 0.37647058823529411242 0.74509803921568629193 1.0"/>
</material>
</visual>
<collision>
<origin xyz="-0.038344380354147181156 0.13356083097909668411 0.0966086928392866362" rpy="1.5707963267948930053 0.16873178976647235094 1.6946894064803318076e-17" />
<geometry>
<mesh filename="package:///arm_01.stl"/>
</geometry>
</collision>
<inertial>
<origin xyz="-0.011676448687552519121 -0.056977296998755547208 -0.0077659352759508522984" rpy="0 0 0"/>
<mass value="0.068946039936000014237" />
<inertia ixx="0.00011581696944377176334" ixy="-2.0078174836869953744e-05"  ixz="5.1566666406941508447e-08" iyy="1.3757156453273847952e-05" iyz="1.2200545237368320735e-07" izz="0.00012497853604730025236" />
</inertial>
</link>

<link name="link_2">
<visual>
<origin xyz="0.061578801533603073903 -0.0038653850637320463779 -0.010746005967108399753" rpy="3.1415926535897864547 0.0033337719077756256328 1.5081084610458925788" />
<geometry>
<mesh filename="package:///servo_motor.stl"/>
</geometry>
<material name="servo_motor_material">
<color rgba="0.30196078431372547213 0.30196078431372547213 0.30196078431372547213 1.0"/>
</material>
</visual>
<collision>
<origin xyz="0.061578801533603073903 -0.0038653850637320463779 -0.010746005967108399753" rpy="3.1415926535897864547 0.0033337719077756256328 1.5081084610458925788" />
<geometry>
<mesh filename="package:///servo_motor.stl"/>
</geometry>
</collision>
<visual>
<origin xyz="-0.014715121890704625784 -0.25145776976873274178 -0.096608692839285095766" rpy="-1.5707963267949007768 -0.16873178976647845717 3.1661387344985894736e-17" />
<geometry>
<mesh filename="package:///arm_02_v3.stl"/>
</geometry>
<material name="arm_02_v3_material">
<color rgba="0.082352941176470587092 0.37647058823529411242 0.74509803921568629193 1.0"/>
</material>
</visual>
<collision>
<origin xyz="-0.014715121890704625784 -0.25145776976873274178 -0.096608692839285095766" rpy="-1.5707963267949007768 -0.16873178976647845717 3.1661387344985894736e-17" />
<geometry>
<mesh filename="package:///arm_02_v3.stl"/>
</geometry>
</collision>
<visual>
<origin xyz="-0.014699460186784977372 -0.25120826082896235976 -0.096608692839286594567" rpy="-1.5707963267948996666 -0.16873178976647185134 -2.1303081429507901892e-17" />
<geometry>
<mesh filename="package:///servo_motor_mg996r_2.stl"/>
</geometry>
<material name="servo_motor_mg996r_2_material">
<color rgba="0.35294117647058825815 0.35294117647058825815 0.35294117647058825815 1.0"/>
</material>
</visual>
<collision>
<origin xyz="-0.014699460186784977372 -0.25120826082896235976 -0.096608692839286594567" rpy="-1.5707963267948996666 -0.16873178976647185134 -2.1303081429507901892e-17" />
<geometry>
<mesh filename="package:///servo_motor_mg996r_2.stl"/>
</geometry>
</collision>
<inertial>
<origin xyz="0.025488788034272388816 -0.0016318541153327625112 -0.020131631218811722739" rpy="0 0 0"/>
<mass value="0.094800804912000019575" />
<inertia ixx="2.2245858218652751287e-05" ixy="4.8583566137487915163e-06"  ixz="-1.3499075868518377579e-05" iyy="9.6461684388112151154e-05" iyz="8.7674576234021511593e-07" izz="8.7297210149627288292e-05" />
</inertial>
</link>

<link name="link_3">
<visual>
<origin xyz="-0.0097793120238246905584 0.011871497516313472831 -0.022999993367229132346" rpy="-3.1415926535892517713 -1.5698159926952166554 1.019232343297800103" />
<geometry>
<mesh filename="package:///servo_motor.stl"/>
</geometry>
<material name="servo_motor_material">
<color rgba="0.30196078431372547213 0.30196078431372547213 0.30196078431372547213 1.0"/>
</material>
</visual>
<collision>
<origin xyz="-0.0097793120238246905584 0.011871497516313472831 -0.022999993367229132346" rpy="-3.1415926535892517713 -1.5698159926952166554 1.019232343297800103" />
<geometry>
<mesh filename="package:///servo_motor.stl"/>
</geometry>
</collision>
<visual>
<origin xyz="-0.16573865283780256363 -0.20178084826721720546 0.090533189292191743047" rpy="-1.2130936787734254434 1.3908996602265506493 -4.468026921284518297e-16" />
<geometry>
<mesh filename="package:///arm_03.stl"/>
</geometry>
<material name="arm_03_material">
<color rgba="0.082352941176470587092 0.37647058823529411242 0.74509803921568629193 1.0"/>
</material>
</visual>
<collision>
<origin xyz="-0.16573865283780256363 -0.20178084826721720546 0.090533189292191743047" rpy="-1.2130936787734254434 1.3908996602265506493 -4.468026921284518297e-16" />
<geometry>
<mesh filename="package:///arm_03.stl"/>
</geometry>
</collision>
<inertial>
<origin xyz="0.0056907977879946496091 0.0024069505050835532552 -0.019125435372435915099" rpy="0 0 0"/>
<mass value="0.039462536016000013261" />
<inertia ixx="9.6557293330483106713e-06" ixy="-5.8520618093744090015e-07"  ixz="6.8670213465759703301e-07" iyy="9.0549303625018349751e-06" iyz="-4.5069774602225283462e-07" izz="5.7676809435977425424e-06" />
</inertial>
</link>

<link name="gripper_base">
<visual>
<origin xyz="0.008999999999999980238 0.062999999999999986566 -0.014000000000000008965" rpy="-1.570796326794896558 -1.570796326794896336 0" />
<geometry>
<mesh filename="package:///gripper_base.stl"/>
</geometry>
<material name="gripper_base_material">
<color rgba="0.3058823529411764941 0.59607843137254901134 0.10588235294117646912 1.0"/>
</material>
</visual>
<collision>
<origin xyz="0.008999999999999980238 0.062999999999999986566 -0.014000000000000008965" rpy="-1.570796326794896558 -1.570796326794896336 0" />
<geometry>
<mesh filename="package:///gripper_base.stl"/>
</geometry>
</collision>
<inertial>
<origin xyz="0.0059759370980568479736 0.026335725347071306524 0.0017004909568270746342" rpy="0 0 0"/>
<mass value="0.039916128384000007512" />
<inertia ixx="2.159395022713237963e-05" ixy="-3.2194518241979545565e-06"  ixz="-7.765373121085322711e-07" iyy="6.1995203710646785804e-06" iyz="-3.2037277197933554032e-06" izz="1.9237955762274728904e-05" />
</inertial>
</link>

<joint name="theta5" type="revolute">
<origin xyz="0.015684077597661424952 -0.0038009564709031856689 -0.028099990916539308028" rpy="1.5707963267944720087 1.569815992695214435 -2.1223603102889403438" />
<parent link="link_3" />
<child link="gripper_base" />
<axis xyz="0 0 1"/>
<limit effort="1" velocity="20" />
<joint_properties friction="0.0"/>
</joint>

<joint name="theta4" type="revolute">
<origin xyz="0.091100573746809188069 -0.010828478939053254315 -0.010729003761872498227" rpy="-1.570796326794906328 -0.6817127064207777476 1.5081084610459019046" />
<parent link="link_2" />
<child link="link_3" />
<axis xyz="0 0 1"/>
<limit effort="1" velocity="20" />
<joint_properties friction="0.0"/>
</joint>

<joint name="theta3" type="revolute">
<origin xyz="-0.023644920167362248886 -0.11764742984986586993 4.8572257327350598644e-17" rpy="3.1415926535897917837 -3.2423642731540817655e-15 2.5427429051385948" />
<parent link="link_1" />
<child link="link_2" />
<axis xyz="0 0 1"/>
<limit effort="1" velocity="20" />
<joint_properties friction="0.0"/>
</joint>

<joint name="theta2" type="revolute">
<origin xyz="0.013418564982389561205 -0.004111803921867322742 -0.040276480175933201955" rpy="-1.5707963267948958919 -1.4388195818050057984 2.9728608638233091632" />
<parent link="waist" />
<child link="link_1" />
<axis xyz="0 0 1"/>
<limit effort="1" velocity="20" />
<joint_properties friction="0.0"/>
</joint>

<joint name="theta1" type="revolute">
<origin xyz="0.0021709824683122797007 0.031524939536076955482 0.028716233202627644561" rpy="3.1415926535897917837 2.3186228305578418841e-15 -2.0901580159072090659" />
<parent link="base" />
<child link="waist" />
<axis xyz="0 0 1"/>
<limit effort="1" velocity="20" />
<joint_properties friction="0.0"/>
</joint>


</robot>
